Workbook

Sheet Dados
A1: id_registro | B1: municipio | C1: data_coleta | D1: preco_venda_rs_litro | E1: bandeira | F1: bairro | G1: revenda | H1: cnpj_revenda | I1: produto | J1: linha_csv_origem
A2: ANP_001 | B2: RECIFE | C2: 2026-09-21 | D2: 6.99 | E2: VIBRA | F2: IMBIRIBEIRA | G2: CUNHA DERIVADOS DE PETROLEO LTDA | H2: 00.216.435/0001-78 | I2: GASOLINA | J2: 29308
A3: ANP_002 | B3: RECIFE | C3: 2026-09-21 | D3: 6.99 | E3: VIBRA | F3: BOA VIAGEM | G3: ESTAÇÃO DE SERVIÇOS BOA VIAGEM LTDA | H3: 02.016.104/0001-10 | I3: GASOLINA | J3: 29329
A4: ANP_003 | B4: RECIFE | C4: 2026-09-21 | D4: 6.97 | E4: BRANCA | F4: CACOTE | G4: POSTO ATENAS LTDA | H4: 02.331.341/0001-75 | I4: GASOLINA | J4: 29326
A5: ANP_004 | B5: RECIFE | C5: 2026-09-21 | D5: 6.97 | E5: RAIZEN | F5: SAN MARTIN | G5: POSTO IBIZA LTDA | H5: 03.281.744/0002-09 | I5: GASOLINA | J5: 29302
A6: ANP_005 | B6: RECIFE | C6: 2026-09-21 | D6: 6.95 | E6: BRANCA | F6: AFOGADOS | G6: BRAZ PETRO COMBUSTÍVEIS LTDA | H6: 05.002.107/0001-92 | I6: GASOLINA | J6: 29324
A7: ANP_006 | B7: RECIFE | C7: 2026-09-21 | D7: 6.97 | E7: VIBRA | F7: VARZEA | G7: POSTO ALBATEX LTDA | H7: 05.557.705/0001-28 | I7: GASOLINA | J7: 29293
A8: ANP_007 | B8: RECIFE | C8: 2026-09-21 | D8: 6.99 | E8: VIBRA | F8: GRACAS | G8: PETRO MIX LTDA | H8: 05.684.913/0001-98 | I8: GASOLINA | J8: 29290
A9: ANP_008 | B9: RECIFE | C9: 2026-09-21 | D9: 6.97 | E9: IPIRANGA | F9: IMBIRIBEIRA | G9: CONSTRUCIPE - COMERCIO, CONSTRUCOES E INCORPORACOES LTDA | H9: 07.193.050/0002-62 | I9: GASOLINA | J9: 29284
A10: ANP_009 | B10: RECIFE | C10: 2026-09-21 | D10: 6.97 | E10: VIBRA | F10: BOA VIAGEM | G10: ORGANIZACAO DE PETROLEO SHOPPING LTDA | H10: 09.044.272/0002-49 | I10: GASOLINA | J10: 29296
A11: ANP_010 | B11: RECIFE | C11: 2026-09-21 | D11: 6.97 | E11: VIBRA | F11: PONTO DE PARADA | G11: A.B. SILVA & CIA LTDA | H11: 10.973.568/0001-42 | I11: GASOLINA | J11: 29299
A12: ANP_011 | B12: RECIFE | C12: 2026-09-21 | D12: 6.99 | E12: VIBRA | F12: BOA VIAGEM | G12: POSTO RECH LTDA | H12: 11.052.812/0001-05 | I12: GASOLINA | J12: 31663
A13: ANP_012 | B13: RECIFE | C13: 2026-09-21 | D13: 6.97 | E13: VIBRA | F13: IMBIRIRBEIRA | G13: PETROCAL PETROLEO CAVALCANTI LIMITADA | H13: 12.781.233/0001-58 | I13: GASOLINA | J13: 29305
... A52: ANP_051 | B52: JABOATAO DOS GUARARAPES | C52: 2026-09-23 | D52: 6.95 | E52: RAIZEN | F52: PIEDADE | G52: CEMOPEL CM PETROLEO LTDA | H52: 69.943.686/0006-65 | I52: GASOLINA | J52: 36066

Sheet Medidas
A1: Medida | B1: Resultado da formula | C1: Como a planilha calcula
A2: Quantidade de postos | B2: =COUNT(Dados!D2:D52) | C2: Conta os 51 precos da coluna D.
A3: Soma dos precos (R$) | B3: =SUM(Dados!D2:D52) | C3: Soma os 51 precos. A media usa esta soma.
A4: Media (R$/litro) | B4: =AVERAGE(Dados!D2:D52) | C4: Soma dividida por 51.
A5: Mediana (R$/litro) | B5: =MEDIAN(Dados!D2:D52) | C5: Com 51 precos, e o 26o valor da lista ordenada.
A6: Moda (R$/litro) | B6: =MODE(Dados!D2:D52) | C6: Preco que mais se repete.
A7: Menor preco (R$/litro) | B7: =MIN(Dados!D2:D52) | C7: Menor valor do conjunto.
A8: Maior preco (R$/litro) | B8: =MAX(Dados!D2:D52) | C8: Maior valor do conjunto.
A9: Amplitude (R$/litro) | B9: =B8-B7 | C9: Maior preco menos o menor preco.
A10: Desvio padrao amostral | B10: =STDEV(Dados!D2:D52) | C10: Raiz da variancia. O divisor e 51 - 1 = 50.
A11: Variancia amostral | B11: =VAR(Dados!D2:D52) | C11: Soma dos desvios ao quadrado, dividida por 50.
A12: Q1, metodo da aula | B12: =SMALL(Dados!D2:D52,13) | C12: 13o preco da lista ordenada. Centro da metade de baixo.
A13: Q3, metodo da aula | B13: =SMALL(Dados!D2:D52,39) | C13: 39o preco da lista ordenada. Centro da metade de cima.
A14: Intervalo interquartil | B14: =B13-B12 | C14: Q3 menos Q1.
A15: Limite inferior do boxplot | B15: =B12-1.5*B14 | C15: Q1 menos 1,5 vezes o intervalo interquartil.
A16: Limite superior do boxplot | B16: =B13+1.5*B14 | C16: Q3 mais 1,5 vezes o intervalo interquartil.
A17: Soma dos desvios ao quadrado | B17: =DEVSQ(Dados!D2:D52) | C17: Base manual do desvio padrao.
A18: Desvio conferido na mao | B18: =SQRT(B17/(B2-1)) | C18: Deve bater com o desvio padrao amostral.

Sheet Frequencia
A1: Preco (R$/litro) | B1: Quantidade de postos | C1: Percentual
A2: 6.89 | B2: =COUNTIF(Dados!D$2:D$52,A2) | C2: =B2/Medidas!B2
A3: 6.93 | B3: =COUNTIF(Dados!D$2:D$52,A3) | C3: =B3/Medidas!B2
A4: 6.95 | B4: =COUNTIF(Dados!D$2:D$52,A4) | C4: =B4/Medidas!B2
A5: 6.97 | B5: =COUNTIF(Dados!D$2:D$52,A5) | C5: =B5/Medidas!B2
A6: 6.98 | B6: =COUNTIF(Dados!D$2:D$52,A6) | C6: =B6/Medidas!B2
A7: 6.99 | B7: =COUNTIF(Dados!D$2:D$52,A7) | C7: =B7/Medidas!B2
A8: Total | B8: =SUM(B2:B7) | C8: =SUM(C2:C7)

Sheet Lista_ordenada
A1: Posicao | B1: Preco ordenado (R$/litro) | C1: Papel no calculo
A2: 1 | B2: =SMALL(Dados!$D$2:$D$52,A2)
A3: 2 | B3: =SMALL(Dados!$D$2:$D$52,A3)
A4: 3 | B4: =SMALL(Dados!$D$2:$D$52,A4)
A5: 4 | B5: =SMALL(Dados!$D$2:$D$52,A5)
A6: 5 | B6: =SMALL(Dados!$D$2:$D$52,A6)
A7: 6 | B7: =SMALL(Dados!$D$2:$D$52,A7)
A8: 7 | B8: =SMALL(Dados!$D$2:$D$52,A8)
A9: 8 | B9: =SMALL(Dados!$D$2:$D$52,A9)
A10: 9 | B10: =SMALL(Dados!$D$2:$D$52,A10)
A11: 10 | B11: =SMALL(Dados!$D$2:$D$52,A11)
A12: 11 | B12: =SMALL(Dados!$D$2:$D$52,A12)
A13: 12 | B13: =SMALL(Dados!$D$2:$D$52,A13)
A14: 13 | B14: =SMALL(Dados!$D$2:$D$52,A14) | C14: Q1, centro da metade de baixo
A15: 14 | B15: =SMALL(Dados!$D$2:$D$52,A15)
A16: 15 | B16: =SMALL(Dados!$D$2:$D$52,A16)
A17: 16 | B17: =SMALL(Dados!$D$2:$D$52,A17)
A18: 17 | B18: =SMALL(Dados!$D$2:$D$52,A18)
A19: 18 | B19: =SMALL(Dados!$D$2:$D$52,A19)
A20: 19 | B20: =SMALL(Dados!$D$2:$D$52,A20)
A21: 20 | B21: =SMALL(Dados!$D$2:$D$52,A21)
A22: 21 | B22: =SMALL(Dados!$D$2:$D$52,A22)
A23: 22 | B23: =SMALL(Dados!$D$2:$D$52,A23)
A24: 23 | B24: =SMALL(Dados!$D$2:$D$52,A24)
A25: 24 | B25: =SMALL(Dados!$D$2:$D$52,A25)
A26: 25 | B26: =SMALL(Dados!$D$2:$D$52,A26)
A27: 26 | B27: =SMALL(Dados!$D$2:$D$52,A27) | C27: Mediana, 26a posicao
A28: 27 | B28: =SMALL(Dados!$D$2:$D$52,A28)
A29: 28 | B29: =SMALL(Dados!$D$2:$D$52,A29)
A30: 29 | B30: =SMALL(Dados!$D$2:$D$52,A30)
A31: 30 | B31: =SMALL(Dados!$D$2:$D$52,A31)
A32: 31 | B32: =SMALL(Dados!$D$2:$D$52,A32)
A33: 32 | B33: =SMALL(Dados!$D$2:$D$52,A33)
A34: 33 | B34: =SMALL(Dados!$D$2:$D$52,A34)
A35: 34 | B35: =SMALL(Dados!$D$2:$D$52,A35)
A36: 35 | B36: =SMALL(Dados!$D$2:$D$52,A36)
A37: 36 | B37: =SMALL(Dados!$D$2:$D$52,A37)
A38: 37 | B38: =SMALL(Dados!$D$2:$D$52,A38)
A39: 38 | B39: =SMALL(Dados!$D$2:$D$52,A39)
A40: 39 | B40: =SMALL(Dados!$D$2:$D$52,A40) | C40: Q3, centro da metade de cima
...

Sheet Como_conferir
A1: Conferencia dos calculos
A3: Abra esta planilha no LibreOffice ou no Excel e deixe as formulas calcularem.
A4: A coluna B da aba Medidas deve mostrar: quantidade 51, soma 355,21, media 6,9649, mediana 6,97, moda 6,95, amplitude 0,10 e desvio padrao amostral 0,0202.
A5: O desvio usa a versao amostral. O divisor e n - 1, isto e, 50. A celula B18 refaz essa conta com a soma dos desvios ao quadrado.
A6: Quartis: n = 51 e impar. A mediana e o 26o preco. Ela sai da lista antes de achar Q1 e Q3. Cada metade fica com 25 precos. Q1 e Q3 sao o 13o preco de cada metade, nas posicoes 13 e 39 da lista completa.
A7: Esse metodo e o da aula. Outro metodo de quartil pode dar numero diferente.
A8: Nenhum preco foi tirado da base. O preco de 6,89 fica no limite inferior do boxplot e continua no conjunto.
A9: Fonte dos precos: ANP, serie historica de precos de combustiveis, setembro de 2026. Recorte de 21 a 27/09/2026. Consulta em 08/10/2026.
